# Java_1101

## 1. Exception

java.lang > Exceptions > Exception

```
java.lang.Object
	java.lang.Throwable (부모)
		java.lang.Exception (자식)
		
Direct Known Subclasses: ... 자식이 많을때는 카테고리로 나누어 본다

The class Exception and its subclasses are a form of Throwable that indicates conditions that a reasonable application might want to catch.
The class Exception and any subclasses that are not also subclasses of RuntimeException are checked exceptions.익셉션 자식중 런타임익셉션이 있는데 얘는 체크드 익셉션이다

```

예외 :: 프로그램을 실행하는 도중에 발생하는 얘기치 못한 상황으로 일종의 버그이다. 버그를 처리하지 않고서는 프로그램을 정상적으로 실행할 수 없다.

Exception 키워드: :memo:

try 

catch 

finally 

throws 

throw  



## 예외처리 계층구조



![예외처리 계층구조](https://user-images.githubusercontent.com/83646543/140239401-d013bc38-12fc-4741-9f64-d7bb50aadafc.jpg)




## Runtime 계열 예외처리

1. 컴파일러가 인식을 못함 컴파일은 되고 실행할때 예외를 발생한다
2. 예외처리를 굳이 명시적으로 할 필요가 없고 소스코드를 수정하기만 하면 된다



#### RuntimeExceptionTest1

java20_Exception > exception.runtime.test > RuntimeExceptionTest1.java

```java
package exception.runtime.test;

public class RuntimeExceptionTest1 {//compile은 됬다

	public static void main(String[] args) {//1 main실행
		 String[ ] str = {
				 "Hello JAVA",
				 "No, I Mean it",
				 "Nice to meet you"
		 };//2 str이라는 배열 1개(3칸) 생성 됨
		 int i=0;//3 
		 while(i <= 3) { //4 //6 //8 //10
			 System.out.println(str[i]);//5 i에0값 //7 i에1값 //9 i에 2값 //11 메모리i str[3]이라는 인덱스가 없어서 여기에서 에러가 난것.
			 i++;
		 }
		 System.out.println("While loop the end...");

	}

}
```

 결과

```
Hello JAVA
No, I Mean it
Nice to meet you
Exception in thread "main" java.lang.ArrayIndexOutOfBoundsException: 3
	at exception.runtime.test.RuntimeExceptionTest1.main(RuntimeExceptionTest1.java:13) //13번째 줄에서 폭탄이 터짐

```



:heavy_check_mark: 출력 됬는데 왜 에러가 낫을까?

​	compile은 됬기 때문에 memory에 올라갔다. 

​	str 데이터는 정상출력 됬는데 프로그램이 정상 종료가 되지 않았다. 

​	(프로그램 비정상 종료 System.out.println("While loop the end..."); <- 이게 출력이 안되었다는 것)

​	예외는 method block`{}` 안에서 <u>줄단위로</u> 발생한다. :memo:



위의 **에러를 해결하고 정상종료** 시키기

```java
package exception.runtime.test;

public class RuntimeExceptionTest1 {

	public static void main(String[] args) {
		 String[ ] str = {
				 "Hello JAVA",
				 "No, I Mean it",
				 "Nice to meet you"
		 };
		 int i=0;
		 while(i < 3) { //이부분으로 에러해결함 
			 System.out.println(str[i]);
			 i++;
		 } // 
		 System.out.println("While loop the end...");
	}//
}//

```

```
Hello JAVA
No, I Mean it
Nice to meet you
While loop the end...
```





### 1- 명시적으로 예외처리하는 방법 - Try catch :memo:

​	class는 chath block으로 bug를 잡는다.

```java
try{ 
    //예외 발생 가능서이 있는 코드가 들어감
    //만약에 예외 발생이 안되면 이부분이 수행된다.
}catch(잡고자하는 예외타입을 인자값으로 넣기){
    //예외를 잡았을때 수행되는 코드가 들어감
    // 만약에 try블락에서 예외가 발생되면 이 부분으로 내려옴
}finally{
    //예외가 발생 하던 안하던 무조건수행되어져야 하는 코드
}
```

ARRAY  `ctrl`+`space` :: ArrayIndexOutOfBoundsException자동완성

Ari `ctrl`+`space` :: ArithmeticException 자동완성

Null `ctrl`+`space` ::NullPointerException 자동완성

Nega `ctrl`+`space` ::NegativeArraySizeException 자동완성





명시적처리가 필요없지만 **명시적처리를 해서 정상종료** 시켜보기(순서확인)

```java
package exception.runtime.test;

public class RuntimeExceptionTest1 {

	public static void main(String[] args) {//1
		 String[ ] str = {//3
				 "Hello JAVA", 
				 "No, I Mean it",
				 "Nice to meet you"
		 };
		 int i=0;
		 while(i <=3) {//5 //8 //11 i==3 //14빠져나오고
			 try {
			 System.out.println(str[i]);//2 str[0] //6 str[1]//9 str[2] //12-1 str[3]이어서 예외발생
			 }catch(ArrayIndexOutOfBoundsException e) { 
				 System.out.println("Nice Cactch!!!");//12-2 예외잘잡음
			 }
			 i++;//4 //7 //10 //13
		 }
		 System.out.println("While loop the end..."); //15 나옴
	}
}

```



Catch는 여러번 할 수 있다. 

하지만 , 그중에서 하나의  catch만 수행한다.



#### RuntimeExceptionTest2

java20_Exception > exception.runtime.test > RuntimeExceptionTest2.java

```java
package exception.runtime.test;

public class RuntimeExceptionTest2 {

	public static void main(String[] args) {
		 String[ ] str = {
				 "Hello JAVA",
				 "No, I Mean it",
				 "Nice to meet you"
		 };
		 int i=0;
		 while(i <=3) {
			 try {
			 System.out.println(str[i]);
			 }catch(NullPointerException e) {
				 System.out.println("Nice Cactch 1!!!");
			 }catch(ArithmeticException e) {
				 System.out.println("Nice Cactch 2!!!");
			 }catch(ArrayIndexOutOfBoundsException e) {
				 System.out.println("Nice Cactch 3!!!");
			 }
			 
			 i++;
		 }
		 System.out.println("While loop the end...");
	}
}

```

```
Hello JAVA
No, I Mean it
Nice to meet you
Nice Cactch 3!!!  <-----------만 출력됨
While loop the end...

```



#### RuntimeExceptionTest3 

java20_Exception > exception.runtime.test > RuntimeExceptionTest3.java

```java
package exception.runtime.test;

public class RuntimeExceptionTest3 {

	public static void main(String[] args) {
		 String[ ] str = {
				 "Hello JAVA",
				 "No, I Mean it",
				 "Nice to meet you"
		 };
		 int i=0;
		 while(i <=3) {
			 try {
			 System.out.println(str[i]);
			 }catch(NullPointerException e) {
				 System.out.println("Nice Cactch 1!!!");
			 }catch(ArithmeticException e) {
				 System.out.println("Nice Cactch 2!!!");
			 }catch(NegativeArraySizeException e) { 
				 System.out.println("Nice Cactch 3!!!");
			 }
			 
			 i++;
		 }
		 System.out.println("While loop the end...");
	}
}

```

결과 :: while loop에 안걸려서 비정상 종료가 되는것

```
Hello JAVA
No, I Mean it
Nice to meet you
Exception in thread "main" java.lang.ArrayIndexOutOfBoundsException: 3
	at exception.runtime.test.RuntimeExceptionTest3.main(RuntimeExceptionTest3.java:14)

```



###  catch

catch는 여러번 할 수 있다

그중에서 하나의  catch만 수행한다.

작은것에서 큰순으로 catch해야한다.:memo:



Exception(큰거)

​          |

RuntimeExeption(작은것들)

--- ArrayIndexOutOfBoundsException

--- ArithmeticException

--- NullPointerException   



#### RuntimeExceptionTest4

java20_Exception > exception.runtime.test > RuntimeExceptionTest4.java

```java
package exception.runtime.test;

public class RuntimeExceptionTest4 {

	public static void main(String[] args) {
		 String[ ] str = {
				 "Hello JAVA",
				 "No, I Mean it",
				 "Nice to meet you"
		 };
		 int i=0;
		 while(i <=3) {
			 try {
			 System.out.println(str[i]);
			 }catch(Exception e) { //이미 처리된(핸들링)
				 System.out.println("Nice Cactch 1!!!");
			 }catch(ArrayIndexOutOfBoundsException e) { //이미 처리된(핸들링)했기 때문에 에러나
				 System.out.println("Nice Cactch 2!!!");
			 }			 
			 i++;
		 }
		 System.out.println("While loop the end...");
	}
}

```

안되는 이유는 부모Exception으로 이미 처리되었기 때문에 ArrayIndexOutOfBoundsException 이부분이 에러난다.

아래와 같이 작은것 -> 큰것 순으로 에러를 해결한다.

``` java
package exception.runtime.test;

public class RuntimeExceptionTest4 {

	public static void main(String[] args) {
		 String[ ] str = {
				 "Hello JAVA",
				 "No, I Mean it",
				 "Nice to meet you"
		 };
		 int i=0;
		 while(i <=3) {
			 try {
			 System.out.println(str[i]);
			 }catch(ArithmeticException e) { //
				 System.out.println("Nice Cactch 1!!!");
			 }catch(Exception e) { //
				 System.out.println("Nice Cactch 2!!!");
			 }			 
			 i++;
		 }
		 System.out.println("While loop the end...");
	}
}

```



## Compile계열  예외처리

###  FileReader

class에서 File을 읽기 위한 기능을 하고있다.

 FileReader() 호출하는 곳으로 예외 객체가 던져진다. 



#### CompileTest1

java20_Exception > exception.compile.test > CompileTest1.java

비정상처리

```java
package exception.compile.test;

import java.io.FileNotFoundException;
import java.io.FileReader;

class FileReading {

	public void readFile(String filename) {
		try {
			FileReader fr = new FileReader(filename);
		} catch (FileNotFoundException e) {			
			e.printStackTrace();
		} //에러중에 unhandled exception 예외처리 안했다라는 뜻 ->해결 서라운드 클릭
		//터진객체로 잡는다.
	
	}
}


public class CompileTest1{
	public static void main(String[] arg) {
		
	}
	
}
```



터진객체 FileReader부분 에러난것을 해결

```java
 catch (FileNotFoundException e) {

 // 서라운드하는 세가지방법 중 택1

// 1 비워두거나

// 2  e.printStackTrace(), e.getMessage()

// 3  System.out.println("파일을 찾지 못했습니다.");	

}
```



정상처리

CompileTest1 호출하기(순서확인)

```java
package exception.compile.test;

import java.io.FileNotFoundException;
import java.io.FileReader;

class FileReading {

	public void readFile(String filename) {
		// File을 읽기위한 기능을 가지고 있는 클래스를 제공하고 있다. ..FileReader생성
		// FileReader 객체를 생성하면 무조건 예외가 터치되도록 만들었다
		try {
			FileReader fr = new FileReader(filename);
			System.out.println("FileReader Creating..."); //2 호출 완료
		} catch (FileNotFoundException e) {
			System.out.println("파일을 찾지 못했습니다.");
		} 
		System.out.println("file...end..."); //3 호출완료된 것과 이게 프린팅됨
	
	}//readFile
}//class


public class CompileTest1{
	public static void main(String[] arg) {
		FileReading fr = new FileReading();
		String path ="C:\\miracom_edu\\utill\\massage.txt";
		
		
		fr.readFile(path);//1 호출
		System.out.println("파일을 정상적으로 읽어들였습니다.");//4 여기까지 출력됨
		
	}
	
}
```

````
파일을 찾지 못했습니다.
file...end...
파일을 정상적으로 읽어들였습니다.
````



## try catch 패턴 



finally 구문이 실행되지 않는 경우 

1. 원인모를 이유에 의해서 컴퓨터의 파워가 꺼진경우
2. finally 블락안에서 또다른 



#### CompileTest2

로컬머신-하드웨어 에는 콘솔시스템 메모리 시스템 등등 자원들과 연결되어 있다

java20_Exception > exception.compile.test > CompileTest2.java

비정상처리

```java
package exception.compile.test;

import java.io.FileNotFoundException;
import java.io.FileReader;

class FileReading2 {

	public void readFile(String filename) {

		try {
			//객체생성의 의미 == Stream자원을 열어서 사용하겠다.
			FileReader fr = new FileReader(filename);
			System.out.println("FileReader Creating..."); 
		} catch (FileNotFoundException e) {
			System.out.println("파일을 찾지 못했습니다.");

		} finally{
            //예외가 발생하던 안하던 무조건생성
            //위에서 열어서 사용한 자원은 무조건 닫아줘야한다          
            fr.close(); //fr은 로컬변수이기때문에 finally안에 선언이 안되있어 에러나  
        }
		System.out.println("file...end..."); 
		
	}//readFile
}//class


public class CompileTest2{
	public static void main(String[] arg) {
		FileReading2 fr = new FileReading2();
		String path ="C:\\miracom_edu\\utill\\massage.txt";
		
		
		fr.readFile(path);
		System.out.println("파일을 정상적으로 읽어들였습니다."); 
	}
	
}

```



기본 정상처리 

변수를 한단계 위 Local  V로 선언 그랫더니 finally 안의 fr.colse();에러남

```java
package exception.compile.test;

import java.io.FileNotFoundException;
import java.io.FileReader;

class FileReading2 {

	public void readFile(String filename) {
		//File을 읽기위한 기능을 가지고 있는 클래스를 제공...FileReader생성
		//FileReader 객체를 생성하면 무조건 예외가 터지도록 만들었다.
			
		FileReader fr = null; //한단계위의 Local V로 선언..
		try {
			//Stream자원을 열여서 사용하겠다 == 객체생성의 의미
			fr = new FileReader(filename);
			
			//
			System.out.println("FileReader  Creating...");
		} catch (FileNotFoundException e) {
			System.out.println("파일을 찾지 못했습니다.");
				
		}finally {
			//위에서 열어서 사용한 자원은 finally블럭안에서 닫아준다.
			fr.close();
		}
		System.out.println("file....end...");	
	}//readFile
}//class


public class CompileTest2{
	public static void main(String[] arg) {
		FileReading2 fr = new FileReading2();
		String path ="C:\\miracom_edu\\utill\\massage.txt";
		
		
		fr.readFile(path);
		System.out.println("파일을 정상적으로 읽어들였습니다."); 
	}
	
}
```



정상처리 

close() :: throws IDExeption 폭탄이 여기로 터지도록 만들어져있다

그래서 fr.close() 를 try catch로 해결 할 수 있다

```java
package exception.compile.test;

import java.io.FileNotFoundException;
import java.io.FileReader;
import java.io.IOException;

class FileReading2 {

	public void readFile(String filename) {
		//File을 읽기위한 기능을 가지고 있는 클래스를 제공...FileReader생성
		//FileReader 객체를 생성하면 무조건 예외가 터지도록 만들었다.
			
		FileReader fr = null; //한단계위의 Local V로 선언..
		try {
			//Stream자원을 열여서 사용하겠다 == 객체생성의 의미
			fr = new FileReader(filename);
			
			//
			System.out.println("FileReader  Creating...");
		} catch (FileNotFoundException e) {
			System.out.println("파일을 찾지 못했습니다.");
				
		}finally {
			//위에서 열어서 사용한 자원은 finally블럭안에서 닫아준다.
			try {
				fr.close();
			} catch (IOException e) {				
				e.printStackTrace();
			}
		}
		System.out.println("file....end...");	
	}//readFile
}//class


public class CompileTest2{
	public static void main(String[] arg) {
		FileReading2 fr = new FileReading2();
		String path ="C:\\miracom_edu\\utill\\massage.txt";
		
		
		fr.readFile(path);
		System.out.println("파일을 정상적으로 읽어들였습니다."); 
	}
	
}
```



## 2- 즉각적으로 처리하지 않고 발생한 예외를 던지는 방법 - Throws

#### CompileTest2

java20_Exception > exception.compile.test >CompileTest2.java

비정상처리

```java
package exception.compile.test;

import java.io.FileNotFoundException;
import java.io.FileReader;
import java.io.IOException;

class FileReading3{
	public void readFile(String filename) {		
		
		FileReader fr = null; 			
		fr = new FileReader(filename);	//예외처리 안되서 이 에러 Throws로 던지기
			
		System.out.println("FileReader  Creating...");					
		System.out.println("file....end...");		
	}//readFile
}//class

public class CompileTest3 {
	public static void main(String[] args) {
		FileReading3 fr = new FileReading3();
		String path = "C:\\miracom_edu\\util\\message.txt";		
		fr.readFile(path);		
		System.out.println("파일을 잘 읽어들였습니다..");
	}
}

```



비정상처리를 1번과 2번으로 Throws해서 정상처리 함

```java
package exception.compile.test;

import java.io.FileNotFoundException;
import java.io.FileReader;
import java.io.IOException;

class FileReading3{
	//1 readFilde메소드를 호출한 곳으로 예외가 던져진다
	public void readFile(String filename) throws FileNotFoundException {		
		
		//발생한 예외객체를 던진다.
		FileReader fr = null; 			
		fr = new FileReader(filename);
			
		System.out.println("FileReader  Creating...");					
		System.out.println("file....end...");		
	}//readFile
}//class

public class CompileTest3 {
	//2 main 메소드(JVM)를 호출한 곳으로 예외가 던져진다 
	public static void main(String[] args) throws FileNotFoundException {
		FileReading3 fr = new FileReading3();
		String path = "C:\\miracom_edu\\util\\message.txt";		
		fr.readFile(path);		//호출지점 !!
		System.out.println("파일을 잘 읽어들였습니다..");
	}
}

```

여기서의 비정상처리를 해결했는데 문제는 닫히지 않았다.



## Exception 결론

- 예외를 처리하는 방법

  1. 명시적으로 그 자리에 즉각적으로 처리
     try~catch

  2. 즉각적으로 처리하지 않고 발생한 예외를 던지는 방법
     throws !

- 명시적 즉각적 둘 다 쓴다

- 예외처리하는 패턴이 존재한다

- throws/catch try 처리

- finally를 함께 써줘야한다

- catch구문에서 예외메세지를 어떻게 출력할지 고민해야한다.

      IOException
          |

     FileNotFoundException



정상처리

#### CompileTest3

java20_Exception > exception.compile.test >CompileTest3.java

```java
package exception.compile.test;
import java.io.FileNotFoundException;
import java.io.FileReader;
import java.io.IOException;

class FileReading3{
	                                            //readFilde메소드를 호출한 곳으로 예외가 던져진다
	public void readFile(String filename) throws FileNotFoundException,IOException {		
		
		//발생한 예외객체를 던진다.		
		FileReader fr = null; 		
		try { //throws의 finally 쓰기위해 사용 
			
			fr = new FileReader(filename);//FileNotFoundException			
			System.out.println("FileReader  Creating...");					
			System.out.println("file....end...");
		}finally {
			fr.close(); //IOException
		}
	}//readFile
}//class

public class CompileTest3 {
	//main 메소드(JVM)를 호출한 곳으로 예외가 던져진다 
	public static void main(String[] args){
		FileReading3 fr = new FileReading3();
		String path = "C:\\\\miracom_edu\\\\utill\\\\message.txt";		
        
        try {
			fr.readFile(path);
		} catch (FileNotFoundException e) {	
			e.printStackTrace(); //자체적으로 출력 path에 없는 파일일경우 여기서 멈춤

		} catch (IOException e) {
			System.out.println(e.getMessage());//e.printStackTrace();와 같음
		}			//호출지점 !!
		System.out.println("파일을 잘 읽어들였습니다..");
	}
}

```

catch문 안에서 사용되어 지는 기능이다

`.printStackTrace()` 출력 `.getMessage()` 리턴



## 3 - UserException(사용자 정의 예외)

1. 내가 직접 Exception클래스를 정의해서 사용

2. 어떤 특정한 조건이 되었을때 내가고의적으로 예외를 발생시키는 것 

   `->`사용자 정의 Exception은 하나의 강력한 제어문으로 사용된다.:memo:

#### UserExceptionTest1

java20_Exception > exception.user.test >UserExceptionTest1.java

비정상 처리

```java
package exception.user.test;


class User{
	public void go() { //5
		//스캐너로 i,j값을 실행시점에서 입력받는 상황
		int i = 10; int j = 0; //6
		System.out.println("1. i,j에 입력된 값으로 연산을 진행합니다..");// 7 출력
		if(j==0) { //8 true
			//ArithmeticException을 발발시켜야 한다==버그 객체 생성 //9 에러나서 출력안됨
			throw new ArithmeticException(); //예외객체는JVM만들었었는데 이때 내가만들었을땐 throw로 사용.
		}
		
		//이부분에서 i/j이런 연산이 진행되는 상황이라고 가정
		//(10/0)... ArithmeticException(부모가 0일때 나는 에러)
		
	}
}

public class UserExceptionTest1 {

	public static void main(String[] args) { //1
		User user = new User(); //2
		System.out.println("2. go() 메소드 호출.."); //3 출력
		user.go();//4
		
		System.out.println("3. 프로그램을 종료합니다..");

	}

}

```



정상처리

```java
package exception.user.test;

class User{
	public void go() throws ArithmeticException { //5

		int i = 10; int j = 0; //6
		System.out.println("1. i,j에 입력된 값으로 연산을 진행합니다..");//7 출력
		if(j==0) { //8 에러 토스
			//ArithmeticException을 발발시켜야 한다==버그 객체 생성 
			throw new ArithmeticException(); //예외객체는JVM만들었었는데 이때 내가만들었을땐 throw로 사용.
		}
		
	
	}
}

public class UserExceptionTest1 {

	public static void main(String[] args) { //1
		User user = new User(); //2
		System.out.println("2. go() 메소드 호출.."); //3 출력
		try {
			user.go(); //4 //9-1
		}catch(ArithmeticException e){
			System.out.println("날라온 폭탄 "); //9-2 잘 캐치함
			
		}				
		System.out.println("3. 프로그램을 종료합니다..");//10 출력 

	}

}

```



예외상속 으로 정상처리 

```java
package exception.user.test;
/*
 * 사용자정의 예외
	1. 내가 직접 Exception클래스를 정의해서 사용
	2. 어떤 특정한 조건이 되었을때 내가고의적으로 예외를 발생시키는 것 

   ->사용자 정의 Exception은 하나의 강력한 제어문으로 사용된다
 */


//Q.해당 클래스를 Exception으로 만들러면 어떻게 선언해야할까? 
class ZeroDevide extends Exception{ //A. 상속을 받는다	
	ZeroDevide(){
		super();
	}
}


class User{
	public void go() throws ZeroDevide { //5
		//스캐너로 i,j값을 실행시점에서 입력받는 상황
		int i = 10; int j = 0; //6
		System.out.println("1. i,j에 입력된 값으로 연산을 진행합니다..");//7 출력
		if(j==0) { //8 에러 토스
			//ArithmeticException을 발발시켜야 한다==버그 객체 생성 
			throw new ZeroDevide(); //예외객체는JVM만들었었는데 이때 내가만들었을땐 throw로 사용.
		}
		
		//이부분에서 i/j이런 연산이 진행되는 상황이라고 가정
		//(10/0)... ArithmeticException(부모가 0일때 나는 에러)
		
	}
}

public class UserExceptionTest1 {

	public static void main(String[] args) { //1
		User user = new User(); //2
		System.out.println("2. go() 메소드 호출.."); //3 출력
		try {
			user.go(); //4 //9-1
		}catch(ZeroDevide e){
			System.out.println("날라온 폭탄 "); //9-2 잘 캐치함 출력
			
		}				
		System.out.println("3. 프로그램을 종료합니다..");//10 출력 

	}

}

```



사용자정의 예외를 catch문 안에 getMessage()넣어 사용

```java
package exception.user.test;
/*
 * 사용자정의 예외
	1. 내가 직접 Exception클래스를 정의해서 사용
	2. 어떤 특정한 조건이 되었을때 내가고의적으로 예외를 발생시키는 것 

   ->사용자 정의 Exception은 하나의 강력한 제어문으로 사용된다
 */


//Q.해당 클래스를 Exception으로 만들러면 어떻게 선언해야할까? 
class ZeroDevide extends Exception{ //A. 상속을 받는다	
	ZeroDevide(){
		this("This is ZeroDevide Exception..");
	}
	//생성자 오버로딩
	ZeroDevide(String message){
		super(message); //2
		
	}

}


class User{
	public void go() throws ZeroDevide {
		
		int i = 10; int j = 0;
		System.out.println("1. i,j에 입력된 값으로 연산을 진행합니다..");
		if(j==0) { 
//			ArithmeticException
//			throw new ZeroDevide();
			throw new ZeroDevide("분모가 0이면 안되요!"); // 1 이것을 return하는게 getMessage()
		}
	}
}

public class UserExceptionTest1 {

	public static void main(String[] args) { 
		User user = new User();
		System.out.println("2. go() 메소드 호출.."); 
		try {
			user.go(); 
		}catch(ZeroDevide e){
//			System.out.println("날라온 폭탄 "); //직접 적기
			System.out.println(e.getMessage());
//			e.printStackTrace();//에러의 족적을 따라가서 그것을 출력해준다-결과에 비정상종료된거아님 /개발시에쓰지만 배포시엔 막음 
			
		}				
		System.out.println("3. 프로그램을 종료합니다..");

	}

}

```



e.printStackTrace();

에러의 족적을 따라가서 그것을 출력해준다

결과에 비정상종료된거 처럼 빨간 글이 보이지만 아니다

해커들의 표적이 되기때문에 잘 안쓴다.

그래서 개발시에쓰지만 배포시엔 막음 



총정리

#### UserExceptionTest1

java20_Exception > exception.user.test >UserExceptionTest1.java

```java
package exception.user.test;

import java.util.Scanner;

class UnderAgeException extends Exception{ 
	UnderAgeException(){
		this("This is UnderAgeException Exception..");
	}
	UnderAgeException(String message){
		super(message); 
		
	}

}

class AdultMovieService{
	public void entrance(int age) throws UnderAgeException {
		if(age >= 19){
			//19세 이상만 성인영화 입장 가능하고 그렇지 않은 경우에는 예약불가\
			System.out.println("티켓 예약완료 되었습니다");
		}else {
			throw new UnderAgeException("아직 미성년자 입니다....");
		}
	}
}

public class UserExceptionTEst2 {

	public static void main(String[] args) {
		AdultMovieService service = new AdultMovieService();
		Scanner sc = new Scanner(System.in);
		System.out.println("나이 입력 ---->");
		int age = sc.nextInt();
		try {
			service.entrance(age);
		}catch(UnderAgeException e){
			System.out.println(e.getMessage());
			
		}finally {
			System.out.println("10시가  되어서 마지막 영화를 상영합니다..");
		}
		System.out.println("극장문을 닫습니다");

	}

}


```

